<robot name="onshape">
<link name="main_body">
<visual>
<origin xyz="-0.090978839083479812189 0.08190149504523690227 0.099279393956395192711" rpy="1.570796326794896558 1.570796326794896336 0" />
<geometry>
<mesh filename="package:///st3125.stl"/>
</geometry>
<material name="st3125_material">
<color rgba="0.031372549019607842702 0 0.97647058823529409022 1.0"/>
</material>
</visual>
<collision>
<origin xyz="-0.090978839083479812189 0.08190149504523690227 0.099279393956395192711" rpy="1.570796326794896558 1.570796326794896336 0" />
<geometry>
<mesh filename="package:///st3125.stl"/>
</geometry>
</collision>
<visual>
<origin xyz="-0.010000000000000000208 0.081901495045236805126 0.045357987389408896406" rpy="1.57079632679489678 -0 -1.7525962493923800721e-30" />
<geometry>
<mesh filename="package:///base_link.stl"/>
</geometry>
<material name="base_link_material">
<color rgba="0.031372549019607842702 0 0.97647058823529409022 1.0"/>
</material>
</visual>
<collision>
<origin xyz="-0.010000000000000000208 0.081901495045236805126 0.045357987389408896406" rpy="1.57079632679489678 -0 -1.7525962493923800721e-30" />
<geometry>
<mesh filename="package:///base_link.stl"/>
</geometry>
</collision>
<visual>
<origin xyz="-0.057021160916520097217 0.057201495045236895598 0.099279393956395095566" rpy="-1.570796326794896558 1.570796326794896336 0" />
<geometry>
<mesh filename="package:///st3125.stl"/>
</geometry>
<material name="st3125_material">
<color rgba="0.031372549019607842702 0 0.97647058823529409022 1.0"/>
</material>
</visual>
<collision>
<origin xyz="-0.057021160916520097217 0.057201495045236895598 0.099279393956395095566" rpy="-1.570796326794896558 1.570796326794896336 0" />
<geometry>
<mesh filename="package:///st3125.stl"/>
</geometry>
</collision>
<inertial>
<origin xyz="-0.073950395348639647031 0.068835154835264630857 0.065147741464481101481" rpy="0 0 0"/>
<mass value="0.54025647521951047914" />
<inertia ixx="0.0016900443708381404986" ixy="1.4890565908838910954e-06"  ixz="-9.6642921823268299573e-07" iyy="0.0016306503727541296275" iyz="1.1064259955710575723e-05" izz="0.0010899715471240337041" />
</inertial>
</link>

<link name="left_upper_hip">
<visual>
<origin xyz="0.017012999556025726333 0.017966838639505690323 0.0040000000000000174305" rpy="-1.570796326794896336 -4.9682480351975715741e-15 -1.5707963267948974462" />
<geometry>
<mesh filename="package:///st3125.stl"/>
</geometry>
<material name="st3125_material">
<color rgba="0.031372549019607842702 0 0.97647058823529409022 1.0"/>
</material>
</visual>
<collision>
<origin xyz="0.017012999556025726333 0.017966838639505690323 0.0040000000000000174305" rpy="-1.570796326794896336 -4.9682480351975715741e-15 -1.5707963267948974462" />
<geometry>
<mesh filename="package:///st3125.stl"/>
</geometry>
</collision>
<visual>
<origin xyz="0.011596160916519899359 -0.012349999999999985989 0.053999999999999999389" rpy="-1.570796326794896558 -0 2.7991757898207133311e-45" />
<geometry>
<mesh filename="package:///servolink_body_hip.stl"/>
</geometry>
<material name="servolink_body_hip_material">
<color rgba="0.97254901960784312376 0.054901960784313724728 0 1.0"/>
</material>
</visual>
<collision>
<origin xyz="0.011596160916519899359 -0.012349999999999985989 0.053999999999999999389" rpy="-1.570796326794896558 -0 2.7991757898207133311e-45" />
<geometry>
<mesh filename="package:///servolink_body_hip.stl"/>
</geometry>
</collision>
<inertial>
<origin xyz="0.027885246175338881253 0.00010484181604821376599 0.024350214853469782927" rpy="0 0 0"/>
<mass value="0.080172015671325883024" />
<inertia ixx="2.3657051081855031419e-05" ixy="-1.5094456635528359557e-08"  ixz="-1.0727114766918093246e-06" iyy="2.2273300260982427292e-05" iyz="3.046592592033075364e-08" izz="1.5241744675129721898e-05" />
</inertial>
</link>

<link name="left_lower_hip">
<visual>
<origin xyz="-0.017566838639505734376 0.014574999999999942168 0.030000000000000047462" rpy="3.141592653589793116 8.3266726846886937747e-16 1.6177811532852511854e-31" />
<geometry>
<mesh filename="package:///st3125.stl"/>
</geometry>
<material name="st3125_material">
<color rgba="0.031372549019607842702 0 0.97647058823529409022 1.0"/>
</material>
</visual>
<collision>
<origin xyz="-0.017566838639505734376 0.014574999999999942168 0.030000000000000047462" rpy="3.141592653589793116 8.3266726846886937747e-16 1.6177811532852511854e-31" />
<geometry>
<mesh filename="package:///st3125.stl"/>
</geometry>
</collision>
<visual>
<origin xyz="-0.017766838639505799086 0.014574999999999990741 0.030000000000000005829" rpy="3.141592653589793116 -1.9190504073756201432e-44 0" />
<geometry>
<mesh filename="package:///servolink_hip_leg.stl"/>
</geometry>
<material name="servolink_hip_leg_material">
<color rgba="0.97254901960784312376 0.054901960784313724728 0 1.0"/>
</material>
</visual>
<collision>
<origin xyz="-0.017766838639505799086 0.014574999999999990741 0.030000000000000005829" rpy="3.141592653589793116 -1.9190504073756201432e-44 0" />
<geometry>
<mesh filename="package:///servolink_hip_leg.stl"/>
</geometry>
</collision>
<inertial>
<origin xyz="0.00023635068560108011149 0.034076421411854400378 0.017700037390337850646" rpy="0 0 0"/>
<mass value="0.079411681455473101532" />
<inertia ixx="2.2778133543996645957e-05" ixy="-4.6527028877141103262e-08"  ixz="8.4590989713590180842e-10" iyy="1.4831784171799459652e-05" iyz="6.5532876999423619634e-08" izz="2.4289610248079340977e-05" />
</inertial>
</link>

<link name="left_upper_leg">
<visual>
<origin xyz="-0.064575000000000104539 0.012350000000000013745 0.036209999999999999132" rpy="1.570796326794896558 1.570796326794896558 0" />
<geometry>
<mesh filename="package:///st3125.stl"/>
</geometry>
<material name="st3125_material">
<color rgba="0.031372549019607842702 0 0.97647058823529409022 1.0"/>
</material>
</visual>
<collision>
<origin xyz="-0.064575000000000104539 0.012350000000000013745 0.036209999999999999132" rpy="1.570796326794896558 1.570796326794896558 0" />
<geometry>
<mesh filename="package:///st3125.stl"/>
</geometry>
</collision>
<visual>
<origin xyz="-0.064574999999999993516 0.012349999999999999867 0.036350000000000000366" rpy="1.570796326794896558 1.570796326794896558 0" />
<geometry>
<mesh filename="package:///hip_servo_knee_link.stl"/>
</geometry>
<material name="hip_servo_knee_link_material">
<color rgba="0.22745098039215685959 0.22745098039215685959 0.22745098039215685959 1.0"/>
</material>
</visual>
<collision>
<origin xyz="-0.064574999999999993516 0.012349999999999999867 0.036350000000000000366" rpy="1.570796326794896558 1.570796326794896558 0" />
<geometry>
<mesh filename="package:///hip_servo_knee_link.stl"/>
</geometry>
</collision>
<inertial>
<origin xyz="-0.07722355640386829867 4.013639740051836877e-07 0.018420109972880304577" rpy="0 0 0"/>
<mass value="0.089161262608861993617" />
<inertia ixx="1.9951940531921516042e-05" ixy="-2.2140931319793392266e-09"  ixz="-1.6082324134655516353e-08" iyy="6.8932866016400311856e-05" iyz="7.8768852023039318915e-12" izz="5.9419271055349912871e-05" />
</inertial>
</link>

<link name="left_lower_leg">
<visual>
<origin xyz="-0.064575000000000007394 0.012349999999999999867 0.036350000000000000366" rpy="1.570796326794896558 1.570796326794896558 0" />
<geometry>
<mesh filename="package:///hip_servo_knee_link.stl"/>
</geometry>
<material name="hip_servo_knee_link_material">
<color rgba="0.22745098039215685959 0.22745098039215685959 0.22745098039215685959 1.0"/>
</material>
</visual>
<collision>
<origin xyz="-0.064575000000000007394 0.012349999999999999867 0.036350000000000000366" rpy="1.570796326794896558 1.570796326794896558 0" />
<geometry>
<mesh filename="package:///hip_servo_knee_link.stl"/>
</geometry>
</collision>
<visual>
<origin xyz="-0.064574999999999924127 0.012350000000000013745 0.036210000000000006071" rpy="1.570796326794896558 1.570796326794896558 0" />
<geometry>
<mesh filename="package:///st3125.stl"/>
</geometry>
<material name="st3125_material">
<color rgba="0.031372549019607842702 0 0.97647058823529409022 1.0"/>
</material>
</visual>
<collision>
<origin xyz="-0.064574999999999924127 0.012350000000000013745 0.036210000000000006071" rpy="1.570796326794896558 1.570796326794896558 0" />
<geometry>
<mesh filename="package:///st3125.stl"/>
</geometry>
</collision>
<inertial>
<origin xyz="-0.07722355640386817377 4.013639740051836877e-07 0.018420109972880311516" rpy="0 0 0"/>
<mass value="0.089161262608861993617" />
<inertia ixx="1.9951940531921516042e-05" ixy="-2.2140931319793342635e-09"  ixz="-1.6082324134650990021e-08" iyy="6.8932866016400054358e-05" iyz="7.8768852023041096061e-12" izz="5.9419271055349668926e-05" />
</inertial>
</link>

<link name="foot">
<visual>
<origin xyz="0.23542499999999999538 0.012349999999999999867 0.036200000000000003009" rpy="1.570796326794896558 1.570796326794896558 0" />
<geometry>
<mesh filename="package:///foot.stl"/>
</geometry>
<material name="foot_material">
<color rgba="0.97254901960784312376 0.054901960784313724728 0 1.0"/>
</material>
</visual>
<collision>
<origin xyz="0.23542499999999999538 0.012349999999999999867 0.036200000000000003009" rpy="1.570796326794896558 1.570796326794896558 0" />
<geometry>
<mesh filename="package:///foot.stl"/>
</geometry>
<surface>
    <friction>
        <ode>
            <mu>0.9</mu> 
            <mu2>0.7</mu2>
        </ode>
    </friction>
</surface>
</collision>
<inertial>
<origin xyz="-0.022670931198493504688 8.6736173798840354721e-18 0.02458571373538560173" rpy="0 0 0"/>
<mass value="0.06548220204090636487" />
<inertia ixx="7.9665054464506340846e-05" ixy="-4.1997948193609496071e-65"  ixz="1.0023908167458286699e-06" iyy="3.9858389155823183874e-05" iyz="1.4462706566809644068e-63" izz="4.6275708045649116139e-05" />
</inertial>
</link>

<joint name="left_foot" type="revolute">
<origin xyz="-0.099999999999999908407 1.3877787807814456755e-17 -3.9999999999991431299e-05" rpy="-1.5777218104420257128e-30 -1.0924123923090688949e-46 0" />
<parent link="left_lower_leg" />
<child link="foot" />
<axis xyz="0 0 1"/>
<limit effort="1" velocity="20" lower="-1.2217304763960306069" upper="1.2217304763960306069"/>
<joint_properties friction="0.0"/>
</joint>

<joint name="left_knee" type="revolute">
<origin xyz="-0.10000000000000008882 2.7755575615628913511e-17 -3.9999999999998370193e-05" rpy="-4.203895392974408274e-45 1.092412392309106233e-46 0" />
<parent link="left_upper_leg" />
<child link="left_lower_leg" />
<axis xyz="0 0 1"/>
<limit effort="1" velocity="20" lower="-2.4434609527920612138" upper="2.4434609527920612138"/>
<joint_properties friction="0.0"/>
</joint>

<joint name="left_hip" type="revolute">
<origin xyz="0.018683161360494256187 0.049999999999999940326 0.017650000000000005962" rpy="1.5707963267948958919 -2.7755575615629071283e-16 -1.570796326794896558" />
<parent link="left_lower_hip" />
<child link="left_upper_leg" />
<axis xyz="0 0 1"/>
<limit effort="1" velocity="20" lower="-1.2217304763960306069" upper="1.2217304763960306069"/>
<joint_properties friction="0.0"/>
</joint>

<joint name="left_in_out" type="revolute">
<origin xyz="0.029362999556025719261 0.017926838639505858486 0.039425000000000022526" rpy="1.570796326794891673 -2.77555756156270942e-16 -8.3838845719492212933e-16" />
<parent link="left_upper_hip" />
<child link="left_lower_hip" />
<axis xyz="0 0 1"/>
<limit effort="1" velocity="20" lower="-0.1745329251994329478" upper="0.1745329251994329478"/>
<joint_properties friction="0.0"/>
</joint>

<joint name="left_hip_around_torso" type="revolute">
<origin xyz="-0.02159616091652009906 0.069551495045236888526 0.099239393956395111074" rpy="-3.141592653589793116 -2.775557561562669977e-16 -5.7211887260545391184e-18" />
<parent link="main_body" />
<child link="left_upper_hip" />
<axis xyz="0 0 1"/>
<limit effort="1" velocity="20" lower="-0.34906585039886589561" upper="0.34906585039886589561"/>
<joint_properties friction="0.0"/>
</joint>

<link name="right_upper_hip">
<visual>
<origin xyz="0.017012999556025920622 0.017966838639506099717 0.004000000000000114575" rpy="-1.570796326794896558 -5.3290705182007569161e-15 -1.5707963267949112129" />
<geometry>
<mesh filename="package:///st3125.stl"/>
</geometry>
<material name="st3125_material">
<color rgba="0.031372549019607842702 0 0.97647058823529409022 1.0"/>
</material>
</visual>
<collision>
<origin xyz="0.017012999556025920622 0.017966838639506099717 0.004000000000000114575" rpy="-1.570796326794896558 -5.3290705182007569161e-15 -1.5707963267949112129" />
<geometry>
<mesh filename="package:///st3125.stl"/>
</geometry>
</collision>
<visual>
<origin xyz="0.011596160916519909767 -0.012349999999999992928 0.054000000000000006328" rpy="-1.570796326794896558 -0 -3.2073176521106427516e-49" />
<geometry>
<mesh filename="package:///servolink_body_hip.stl"/>
</geometry>
<material name="servolink_body_hip_material">
<color rgba="0.97254901960784312376 0.054901960784313724728 0 1.0"/>
</material>
</visual>
<collision>
<origin xyz="0.011596160916519909767 -0.012349999999999992928 0.054000000000000006328" rpy="-1.570796326794896558 -0 -3.2073176521106427516e-49" />
<geometry>
<mesh filename="package:///servolink_body_hip.stl"/>
</geometry>
</collision>
<inertial>
<origin xyz="0.027885246175338843089 0.00010484181604840623898 0.024350214853469862725" rpy="0 0 0"/>
<mass value="0.080172015671325883024" />
<inertia ixx="2.3657051081855061912e-05" ixy="-1.5094456635592214592e-08"  ixz="-1.0727114766918112305e-06" iyy="2.2273300260982440845e-05" iyz="3.0465925920292762889e-08" izz="1.5241744675129713428e-05" />
</inertial>
</link>

<link name="right_lower_hip">
<visual>
<origin xyz="-0.017566838639505810704 -0.01457499999999999768 0.0061000000000000012546" rpy="0 2.0745785858558869992e-44 6.4292163775512551824e-29" />
<geometry>
<mesh filename="package:///st3125.stl"/>
</geometry>
<material name="st3125_material">
<color rgba="0.031372549019607842702 0 0.97647058823529409022 1.0"/>
</material>
</visual>
<collision>
<origin xyz="-0.017566838639505810704 -0.01457499999999999768 0.0061000000000000012546" rpy="0 2.0745785858558869992e-44 6.4292163775512551824e-29" />
<geometry>
<mesh filename="package:///st3125.stl"/>
</geometry>
</collision>
<visual>
<origin xyz="-0.017766838639505788677 -0.01457499999999999768 0.0061000000000000012546" rpy="0 3.5890209535306877795e-43 0" />
<geometry>
<mesh filename="package:///servolink_hip_leg.stl"/>
</geometry>
<material name="servolink_hip_leg_material">
<color rgba="0.97254901960784312376 0.054901960784313724728 0 1.0"/>
</material>
</visual>
<collision>
<origin xyz="-0.017766838639505788677 -0.01457499999999999768 0.0061000000000000012546" rpy="0 3.5890209535306877795e-43 0" />
<geometry>
<mesh filename="package:///servolink_hip_leg.stl"/>
</geometry>
</collision>
<inertial>
<origin xyz="0.00023635068560102899136 -0.034076421411854448951 0.018399962609662177254" rpy="0 0 0"/>
<mass value="0.079411681455473101532" />
<inertia ixx="2.2778133543996662897e-05" ixy="4.6527028877126161072e-08"  ixz="-8.4590989713337053235e-10" iyy="1.4831784171799459652e-05" iyz="6.5532876999425631337e-08" izz="2.4289610248079361306e-05" />
</inertial>
</link>

<link name="right_upper_leg">
<visual>
<origin xyz="-0.064574999999999702083 0.012350000000000048439 0.036209999999999964437" rpy="1.570796326794896558 1.570796326794896558 0" />
<geometry>
<mesh filename="package:///st3125.stl"/>
</geometry>
<material name="st3125_material">
<color rgba="0.031372549019607842702 0 0.97647058823529409022 1.0"/>
</material>
</visual>
<collision>
<origin xyz="-0.064574999999999702083 0.012350000000000048439 0.036209999999999964437" rpy="1.570796326794896558 1.570796326794896558 0" />
<geometry>
<mesh filename="package:///st3125.stl"/>
</geometry>
</collision>
<visual>
<origin xyz="-0.064574999999999993516 0.012350000000000013745 0.036349999999999965672" rpy="1.570796326794896558 1.570796326794896558 0" />
<geometry>
<mesh filename="package:///hip_servo_knee_link.stl"/>
</geometry>
<material name="hip_servo_knee_link_material">
<color rgba="0.22745098039215685959 0.22745098039215685959 0.22745098039215685959 1.0"/>
</material>
</visual>
<collision>
<origin xyz="-0.064574999999999993516 0.012350000000000013745 0.036349999999999965672" rpy="1.570796326794896558 1.570796326794896558 0" />
<geometry>
<mesh filename="package:///hip_servo_knee_link.stl"/>
</geometry>
</collision>
<inertial>
<origin xyz="-0.077223556403868007236 4.0136397403524885747e-07 0.018420109972880273352" rpy="0 0 0"/>
<mass value="0.089161262608861993617" />
<inertia ixx="1.9951940531921516042e-05" ixy="-2.2140931319650227981e-09"  ixz="-1.608232413465526489e-08" iyy="6.8932866016399783307e-05" iyz="7.8768851997890524133e-12" izz="5.9419271055349411428e-05" />
</inertial>
</link>

<link name="right_lower_leg">
<visual>
<origin xyz="-0.064575000000000007394 0.012349999999999999867 0.036349999999999965672" rpy="1.570796326794896558 1.570796326794896558 0" />
<geometry>
<mesh filename="package:///hip_servo_knee_link.stl"/>
</geometry>
<material name="hip_servo_knee_link_material">
<color rgba="0.22745098039215685959 0.22745098039215685959 0.22745098039215685959 1.0"/>
</material>
</visual>
<collision>
<origin xyz="-0.064575000000000007394 0.012349999999999999867 0.036349999999999965672" rpy="1.570796326794896558 1.570796326794896558 0" />
<geometry>
<mesh filename="package:///hip_servo_knee_link.stl"/>
</geometry>
</collision>
<visual>
<origin xyz="-0.064574999999999424527 0.012350000000000124767 0.036209999999999964437" rpy="1.570796326794896558 1.570796326794896558 0" />
<geometry>
<mesh filename="package:///st3125.stl"/>
</geometry>
<material name="st3125_material">
<color rgba="0.031372549019607842702 0 0.97647058823529409022 1.0"/>
</material>
</visual>
<collision>
<origin xyz="-0.064574999999999424527 0.012350000000000124767 0.036209999999999964437" rpy="1.570796326794896558 1.570796326794896558 0" />
<geometry>
<mesh filename="package:///st3125.stl"/>
</geometry>
</collision>
<inertial>
<origin xyz="-0.077223556403867812947 4.0136397408612070337e-07 0.018420109972880273352" rpy="0 0 0"/>
<mass value="0.089161262608861993617" />
<inertia ixx="1.9951940531921516042e-05" ixy="-2.2140931319078096103e-09"  ixz="-1.6082324134655086219e-08" iyy="6.8932866016399417389e-05" iyz="7.8768851991489503285e-12" izz="5.9419271055349038733e-05" />
</inertial>
</link>

<link name="foot_2">
<visual>
<origin xyz="0.23542499999999999538 0.012349999999999999867 0.036200000000000009948" rpy="1.570796326794896558 1.570796326794896558 0" />
<geometry>
<mesh filename="package:///foot.stl"/>
</geometry>
<material name="foot_material">
<color rgba="0.97254901960784312376 0.054901960784313724728 0 1.0"/>
</material>
</visual>
<collision>
<origin xyz="0.23542499999999999538 0.012349999999999999867 0.036200000000000009948" rpy="1.570796326794896558 1.570796326794896558 0" />
<geometry>
<mesh filename="package:///foot.stl"/>
</geometry>
<surface>
    <friction>
        <ode>
            <mu>0.9</mu> 
            <mu2>0.7</mu2>
        </ode>
    </friction>
</surface>
</collision>
<inertial>
<origin xyz="-0.022670931198493504688 8.6736173798840354721e-18 0.024585713735385608669" rpy="0 0 0"/>
<mass value="0.06548220204090636487" />
<inertia ixx="7.9665054464506340846e-05" ixy="-1.9640875806605470927e-50"  ixz="1.0023908167458286699e-06" iyy="3.9858389155823183874e-05" iyz="-1.8560402354549326611e-48" izz="4.6275708045649116139e-05" />
</inertial>
</link>

<joint name="right_foot" type="revolute">
<origin xyz="-0.099999999999999408806 1.249000902703301108e-16 -4.000000000001224798e-05" rpy="-6.2975486165559455013e-17 -6.2785316187098858277e-32 -7.0997481469891062487e-30" />
<parent link="right_lower_leg" />
<child link="foot_2" />
<axis xyz="0 0 1"/>
<limit effort="1" velocity="20" lower="-1.2217304763960306069" upper="1.2217304763960306069"/>
<joint_properties friction="0.0"/>
</joint>

<joint name="right_knee" type="revolute">
<origin xyz="-0.099999999999999686362 4.1633363423443370266e-17 -3.9999999999984492405e-05" rpy="3.5219910549969984548e-17 -8.4077907859489024255e-45 -7.8886090522101180541e-31" />
<parent link="right_upper_leg" />
<child link="right_lower_leg" />
<axis xyz="0 0 1"/>
<limit effort="1" velocity="20" lower="-2.4434609527920612138" upper="2.4434609527920612138"/>
<joint_properties friction="0.0"/>
</joint>

<joint name="right_hip" type="revolute">
<origin xyz="0.018683161360494193737 -0.050000000000000002776 0.018450000000000021938" rpy="-1.57079632679489678 7.8886090522101180541e-30 1.570796326794896558" />
<parent link="right_lower_hip" />
<child link="right_upper_leg" />
<axis xyz="0 0 1"/>
<limit effort="1" velocity="20" lower="-1.2217304763960306069" upper="1.2217304763960306069"/>
<joint_properties friction="0.0"/>
</joint>

<joint name="right_in_out" type="revolute">
<origin xyz="0.029362999556025615178 -0.018283161360493918601 0.039425000000000237632" rpy="-1.5707963267949018871 -6.7649150867249521185e-29 -1.3921856581593558197e-14" />
<parent link="right_upper_hip" />
<child link="right_lower_hip" />
<axis xyz="0 0 1"/>
<limit effort="1" velocity="20" lower="-0.1745329251994329478" upper="0.1745329251994329478"/>
<joint_properties friction="0.0"/>
</joint>

<joint name="right_hip_around_torso" type="revolute">
<origin xyz="-0.12640383908348010178 0.069551495045236791381 0.099239393956395305363" rpy="3.141592653589793116 7.703719777548948886e-33 -3.141592653589793116" />
<parent link="main_body" />
<child link="right_upper_hip" />
<axis xyz="0 0 1"/>
<limit effort="1" velocity="20" lower="-0.34906585039886589561" upper="0.34906585039886589561"/>
<joint_properties friction="0.0"/>
</joint>


</robot>
